Workbook

Sheet Risultati
B1: Ragione sociale | C1: Partita IVA | D1: Chiusura bilancio | E1: Modello di contabilità | F1: TOT. VAL. DELLA PRODUZIONE migl EUR | G1: Ricavi vendite e prestazioni migl EUR | H1: Var. rimanenze prodotti migl EUR | I1: Materie prime e consumo migl EUR | J1: Variazione materie migl EUR | K1: Servizi migl EUR | L1: Totale costi del personale migl EUR | M1: Oneri diversi di gestione migl EUR | N1: Godimento beni di terzi migl EUR | O1: TOT Ammortamenti e svalut. migl EUR | P1: Accantonamenti per rischi migl EUR | Q1: Altri accantonamenti migl EUR | R1: TOTALE PROVENTI E ONERI FINANZIARI migl EUR | S1: TOTALE RETTIFICHE ATT. FINANZ. migl EUR | T1: TOTALE PROVENTI/ONERI STRAORDINARI migl EUR | U1: Totale Imposte sul reddito correnti, differite e anticipate migl EUR | V1: UTILE/PERDITA DI ESERCIZIO migl EUR | W1: Dipendenti | X1: Trend Ricavi n-1 % EUR | Y1: Trend Ricavi a 3 anni % EUR | Z1: Trend Ricavi a 5 anni % EUR | AA1: Trend EBITDA a 5 anni % EUR | AB1: TOTALE ATTIVO migl EUR | AC1: Cred. vs Clienti entro migl EUR | AD1: Cred. vs Clienti oltre migl EUR | AE1: TOTALE RIMANENZE migl EUR | AF1: Immobilizzazioni materiali destinate alla vendita migl EUR | AG1: TOTALE PATRIMONIO NETTO migl EUR | AH1: Fornitori entro migl EUR | AI1: Fornitori oltre migl EUR | AJ1: DEBITI A BREVE migl EUR | AK1: Debiti Finanziari migl EUR | AL1: TOT. DISPON. LIQUIDE migl EUR | AM1: Attività finanziarie per la gestione accentrata della tesoreria migl EUR | AN1: ATECO 2007 codice | AO1: ATECO 2007 descrizione | AP1: CREDITI VERSO SOCI migl EUR | AQ1: TOTALE IMMOB. IMMATERIALI migl EUR | AR1: TOTALE IMMOB. MATERIALI migl EUR | AS1: TOTALE IMMOB. FINANZIARIE migl EUR | AT1: TOTALE CREDITI migl EUR | AU1: TOTALE ATTIVITA' FINANZIARIE migl EUR | AV1: TOTALE DEBITI migl EUR | AW1: RATEI E RISCONTI migl EUR | AX1: RATEI E RISCONTI migl EUR | AY1: EBITDA migl EUR n-4
A2: 1. | B2: ESSELUNGA SPA | C2: 04916380159 | D2: 45291 | E2: Dettagliato | F2: 9120646 | G2: 9038616 | H2: 0 | I2: 6285561 | J2: 0 | K2: 1015920 | L2: 1052480 | M2: 99536 | N2: 25090 | O2: 406552 | P2: 23291 | Q2: 0 | R2: -103005 | S2: 58071 | T2: 1031 | U2: 39284 | V2: 129029 | W2: 23967 | X2: 5.910202 | Y2: 7.1247441 | Z2: 14.224044 | AA2: -11.973027 | AB2: 7890573 | AC2: 263230 | AD2: 0 | AE2: 565651 | AF2: 0 | AG2: 2200792 | AH2: 1693049 | AI2: 0 | AJ2: 2359478 | AK2: 3192105 | AL2: 252746 | AM2: 32110 | AN2: 471100 | AO2: Commercio al dettaglio in esercizi non specializzati con prevalenza di prodotti alimentari e bevande | AP2: 0 | AQ2: 220145 | AR2: 5222483 | AS2: 1159374 | AT2: 402192 | AU2: 53307 | AV2: 5393411 | AW2: 177519 | AX2: 14675 | AY2: 702930
A3: 2. | B3: LIDL ITALIA S.R.L. | C3: 02275030233 | D3: 45351 | E3: Dettagliato | F3: 7230231 | G3: 7158326 | H3: 0 | I3: 5027140 | J3: 217103 | K3: 657621 | L3: 673251 | M3: 47150 | N3: 84069 | O3: 226867 | P3: 1872 | Q3: 262 | R3: -24069 | S3: 558 | T3: 0 | U3: 77452 | V3: 193932 | W3: 20814 | X3: 7.04756 | Y3: 21.644515 | Z3: 38.929638 | AA3: 37.408386 | AB3: 3812743 | AC3: 2774 | AD3: 0 | AE3: 455584 | AF3: 3894 | AG3: 1902923 | AH3: 958299 | AI3: 6259 | AJ3: 1432997 | AK3: 657261 | AL3: 72756 | AM3: 212878 | AN3: 469000 | AO3: Commercio all'ingrosso non specializzato | AP3: 0 | AQ3: 111652 | AR3: 2747980 | AS3: 8537 | AT3: 182206 | AU3: 212878 | AV3: 1799919 | AW3: 20614 | AX3: 17256 | AY3: 379717
A4: 3. | B4: A.I.A. - AGRICOLA ITALIANA ALIMENTARE - S.P.A. | C4: 00233470236 | D4: 45291 | E4: Dettagliato | F4: 4814669 | G4: 4712306 | H4: 440 | I4: 4090111 | J4: 5280 | K4: 442257 | L4: 57265 | M4: 13255 | N4: 5091 | O4: 94636 | P4: 0 | Q4: 0 | R4: -17934 | S4: 0 | T4: 0 | U4: 21355 | V4: 67486 | W4: 687 | X4: 11.802779 | Y4: 24.983947 | Z4: 36.766654 | AA4: 60.629406 | AB4: 1576836 | AC4: 397265 | AD4: 0 | AE4: 27726 | AF4: 0 | AG4: 475818 | AH4: 365804 | AI4: 0 | AJ4: 825229 | AK4: 615258 | AL4: 49282 | AM4: 0 | AN4: 463210 | AO4: Commercio all'ingrosso di carne fresca, congelata e surgelata | AP4: 0 | AQ4: 150 | AR4: 523919 | AS4: 275760 | AT4: 585927 | AU4: 111758 | AV4: 1068841 | AW4: 3702 | AX4: 2313 | AY4: 125388
A5: 4. | B5: PAC 2000 A SOCIETA' COOPERATIVA | C5: 00163040546 | D5: 45291 | E5: Dettagliato | F5: 4537962 | G5: 3939071 | H5: 0 | I5: 4036095 | J5: -9543 | K5: 337244 | L5: 40571 | M5: 13047 | N5: 31947 | O5: 35158 | P5: 1000 | Q5: 12712 | R5: 10320 | S5: 0 | T5: 0 | U5: 7868 | V5: 42184 | W5: 790 | X5: 9.467291 | Y5: 17.621953 | Z5: 63.940179 | AA5: 18.448107 | AB5: 1636025 | AC5: 277213 | AD5: 0 | AE5: 160043 | AF5: 0 | AG5: 784103 | AH5: 704677 | AI5: 0 | AJ5: 784557 | AK5: 48096 | AL5: 87591 | AM5: 77 | AN5: 463890 | AO5: Commercio all'ingrosso di altri prodotti alimentari | AP5: 3026 | AQ5: 37853 | AR5: 365022 | AS5: 386597 | AT5: 540065 | AU5: 50083 | AV5: 815565 | AW5: 4939 | AX5: 5745 | AY5: 63226
A6: 5. | B6: COOP ALLEANZA 3.0 SOCIETA' COOPERATIVA | C6: 03503411203 | D6: 45291 | E6: Dettagliato | F6: 4372943 | G6: 3895925 | H6: -20509 | I6: 3028993 | J6: -16617 | K6: 462223 | L6: 596887 | M6: 79107 | N6: 145796 | O6: 106806 | P6: 5655 | Q6: 5500 | R6: 93308 | S6: -16956 | T6: 0 | U6: 14932 | V6: 20013 | W6: 16244 | X6: 1.7454805 | Y6: -3.8114223 | Z6: 6.7572385 | AA6: -148.41824 | AB6: 6246398 | AC6: 217674 | AD6: 8934 | AE6: 489231 | AF6: 0 | AG6: 1586205 | AH6: 703634 | AI6: 145 | AJ6: 3427654 | AK6: 3587640 | AL6: 225861 | AM6: 35328 | AN6: 471120 | AO6: Supermercati | AP6: 0 | AQ6: 173036 | AR6: 1077666 | AS6: 2652270 | AT6: 338663 | AU6: 1273876 | AV6: 4475076 | AW6: 3580 | AX6: 15795 | AY6: -135071
A7: 6. | B7: GS SPA | C7: 12683790153 | D7: 45291 | E7: Dettagliato | F7: 4481915 | G7: 3836122 | H7: 0 | I7: 3279750 | J7: 9279 | K7: 512822 | L7: 484359 | M7: 23033 | N7: 201389 | O7: 83298 | P7: 501 | Q7: 0 | R7: -15793 | S7: 0 | T7: 0 | U7: 435 | V7: -128746 | W7: 9392 | X7: -0.19279142 | Y7: -1.2921669 | Z7: 10.353829 | AA7: 88.887452 | AB7: 1548298 | AC7: 131231 | AD7: 1153 | AE7: 366643 | AF7: 0 | AG7: 152359 | AH7: 747001 | AI7: 0 | AJ7: 1303331 | AK7: 13 | AL7: 37962 | AM7: 0 | AN7: 471100 | AO7: Commercio al dettaglio in esercizi non specializzati con prevalenza di prodotti alimentari e bevande | AP7: 0 | AQ7: 242393 | AR7: 103985 | AS7: 340820 | AT7: 418326 | AU7: 0 | AV7: 1309071 | AW7: 1409 | AX7: 38171 | AY7: -15469
A8: 7. | B8: MD S.P.A. | C8: 03185210618 | D8: 45291 | E8: Dettagliato | F8: 3688201 | G8: 3591475 | H8: 0 | I8: 2769990 | J8: 4494 | K8: 309641 | L8: 281347 | M8: 16163 | N8: 87258 | O8: 89695 | P8: 3332 | Q8: 0 | R8: -11047 | S8: 0 | T8: 0 | U8: 34984 | V8: 80249 | W8: 7823 | X8: 7.7535384 | Y8: 19.540189 | Z8: 44.543083 | AA8: 58.204473 | AB8: 1742231 | AC8: 127902 | AD8: 0 | AE8: 187440 | AF8: 0 | AG8: 580263 | AH8: 712285 | AI8: 0 | AJ8: 967290 | AK8: 321976 | AL8: 195835 | AM8: 0 | AN8: 471120 | AO8: Supermercati | AP8: 0 | AQ8: 377888 | AR8: 607643 | AS8: 186865 | AT8: 173715 | AU8: 0 | AV8: 1116038 | AW8: 8794 | AX8: 12845 | AY8: 136517
A9: 8. | B9: SPESA INTELLIGENTE S.P.A. | C9: 02416840235 | D9: 45291 | E9: Dettagliato | F9: 3181536 | G9: 3162613 | H9: 0 | I9: 2472185 | J9: 8250 | K9: 212848 | L9: 225039 | M9: 11545 | N9: 13125 | O9: 67213 | P9: 0 | Q9: 0 | R9: 2678 | S9: 0 | T9: 0 | U9: 45598 | V9: 128413 | W9: 5557 | X9: 11.617276 | Y9: 26.84426 | Z9: 47.69814 | AA9: 66.959461 | AB9: 1359065 | AC9: 60566 | AD9: 0 | AE9: 118661 | AF9: 0 | AG9: 824811 | AH9: 402095 | AI9: 0 | AJ9: 522944 | AK9: 10515 | AL9: 37692 | AM9: 1561 | AN9: 471100 | AO9: Commercio al dettaglio in esercizi non specializzati con prevalenza di prodotti alimentari e bevande | AP9: 0 | AQ9: 18418 | AR9: 1074920 | AS9: 858 | AT9: 105277 | AU9: 1561 | AV9: 522997 | AW9: 8111 | AX9: 1678 | AY9: 142876
A10: 9. | B10: UNICOOP FIRENZE SOCIETA' COOPERATIVA IN SIGLA UNICOOP FIRENZE SC | C10: 00407780485 | D10: 45291 | E10: Dettagliato | F10: 3130808 | G10: 3014665 | H10: 0 | I10: 2397666 | J10: 10511 | K10: 246066 | L10: 290560 | M10: 50019 | N10: 8481 | O10: 99612 | P10: 0 | Q10: 26954 | R10: 37422 | S10: -1420 | T10: 0 | U10: 11377 | V10: 25564 | W10: 8172 | X10: 11.1997 | Y10: 24.896167 | Z10: 26.468763 | AA10: -36.931897 | AB10: 3806693 | AC10: 89563 | AD10: 0 | AE10: 143722 | AF10: 20841 | AG10: 1780860 | AH10: 429863 | AI10: 0 | AJ10: 1784883 | AK10: 1401171 | AL10: 210389 | AM10: 5040 | AN10: 471120 | AO10: Supermercati | AP10: 0 | AQ10: 36851 | AR10: 1375389 | AS10: 1252493 | AT10: 241745 | AU10: 513026 | AV10: 1934073 | AW10: 964 | AX10: 12236 | AY10: 159434
A11: 10. | B11: CONAD NORD OVEST SOCIETA' COOPERATIVA | C11: 01977130473 | D11: 45291 | E11: Dettagliato | F11: 3361341 | G11: 2997446 | H11: 0 | I11: 3024044 | J11: 25080 | K11: 202421 | L11: 31138 | M11: 6359 | N11: 0 | O11: 25543 | P11: 0 | Q11: 0 | R11: 15910 | S11: 0 | T11: -448 | U11: 1315 | V11: 60903 | W11: 484 | X11: 7.7557885 | Y11: 15.880226 | Z11: 24.223553 | AA11: 36.192216 | AB11: 1932957 | AC11: 110623 | AD11: 3132 | AE11: 129504 | AF11: 0 | AG11: 922469 | AH11: 367207 | AI11: 0 | AJ11: 616647 | AK11: 505577 | AL11: 156745 | AM11: 0 | AN11: 463920 | AO11: Commercio all'ingrosso non specializzato di prodotti alimentari, bevande e tabacco | AP11: 0 | AQ11: 75454 | AR11: 117115 | AS11: 596019 | AT11: 644162 | AU11: 213958 | AV11: 977455 | AW11: 4802 | AX11: 0 | AY11: 53086
A12: 11. | B12: AGRICOLA TRE VALLI - SOCIETA' COOPERATIVA | C12: 02447620234 | D12: 45291 | E12: Dettagliato | F12: 2938830 | G12: 2912605 | H12: 10406 | I12: 2192596 | J12: -3417 | K12: 334610 | L12: 300149 | M12: 10453 | N12: 101593 | O12: 1875 | P12: 0 | Q12: 0 | R12: -758 | S12: 0 | T12: 0 | U12: 23 | V12: 191 | W12: 6553 | X12: 13.829881 | Y12: 21.306228 | Z12: 31.697986 | AA12: -31.006061 | AB12: 459487 | AC12: 163391 | AD12: 0 | AE12: 237989 | AF12: 0 | AG12: 23651 | AH12: 286045 | AI12: 0 | AJ12: 411046 | AK12: 44544 | AL12: 622 | AM12: 0 | AN12: 101200 | AO12: Produzione di carne di volatili e prodotti della loro macellazione (attività dei mattatoi) | AP12: 0 | AQ12: 84 | AR12: 11237 | AS12: 69 | AT12: 209214 | AU12: 0 | AV12: 411046 | AW12: 244 | AX12: 271 | AY12: 4125
A13: 12. | B13: MAXI DI S.R.L. | C13: 00542090238 | D13: 45291 | E13: Dettagliato | F13: 2731583 | G13: 2690365 | H13: 0 | I13: 2036704 | J13: -23468 | K13: 251200 | L13: 226369 | M13: 17801 | N13: 40000 | O13: 83683 | P13: 0 | Q13: 800 | R13: 1450 | S13: 0 | T13: 0 | U13: 25213 | V13: 74731 | W13: 6762 | X13: 8.9094903 | Y13: 12.712543 | Z13: 26.621083 | AA13: 45.118172 | AB13: 1357200 | AC13: 28711 | AD13: 727 | AE13: 292224 | AF13: 0 | AG13: 719062 | AH13: 320714 | AI13: 0 | AJ13: 444956 | AK13: 231308 | AL13: 123845 | AM13: 0 | AN13: 471120 | AO13: Supermercati | AP13: 0 | AQ13: 36444 | AR13: 771154 | AS13: 68729 | AT13: 58277 | AU13: 0 | AV13: 614979 | AW13: 8392 | AX13: 6528 | AY13: 125537
... A30: 30. | B30: UNILEVER ITALIA MKT. OPERATIONS SRL - FATTA PRECISAZIONE CHE DETT A DENOMINAZIONE POTRA' ESSERE SCRITTA CON O SENZA IL PUNTO DOPO LA PAROLA MKT. | C30: 06397510964 | D30: 45291 | E30: Dettagliato | F30: 1504405.3 | G30: 1491775.7 | H30: 0 | I30: 686433.15 | J30: 1992.151 | K30: 671147.94 | L30: 49687.472 | M30: 12288.572 | N30: 62809.812 | O30: 18927.732 | P30: 676 | Q30: 349.322 | R30: 12945.164 | S30: 0 | T30: 0 | U30: 3732.163 | V30: 9306.114 | W30: 413 | X30: 3.5954845 | Y30: 4.8985658 | Z30: 1.3989368 | AA30: -21.773708 | AB30: 668272.15 | AC30: 120897.16 | AD30: 0 | AE30: 724.488 | AF30: 0 | AG30: 368451.94 | AH30: 179406.3 | AI30: 0 | AJ30: 270209.35 | AK30: 2123.702 | AL30: 370.935 | AM30: 474784.56 | AN30: 469000 | AO30: Commercio all'ingrosso non specializzato | AP30: 0 | AQ30: 17545.727 | AR30: 23774.561 | AS30: 0 | AT30: 151028.1 | AU30: 474784.56 | AV30: 272530.74 | AW30: 1452.353 | AX30: 43.778 | AY30: 24315.156
A31: 31. | B31: IPERAL SUPERMERCATI S.P.A. | C31: 11023300962 | D31: 45291 | E31: Dettagliato | F31: 1405942 | G31: 1397079 | H31: 0 | I31: 1019857.3 | J31: -1749.411 | K31: 113904.02 | L31: 114412.65 | M31: 3240.785 | N31: 21907.026 | O31: 24820.274 | P31: 0 | Q31: 0 | R31: 2832.443 | S31: 0 | T31: 0 | U31: 29629.077 | V31: 82752.702 | W31: 4193 | X31: 17.24626 | Y31: 33.92064 | Z31: 0 | AA31: 0 | AB31: 531958.26 | AC31: 27864.389 | AD31: 0 | AE31: 51022.823 | AF31: 0 | AG31: 298673.9 | AH31: 120255.72 | AI31: 0 | AJ31: 220620.12 | AK31: 0 | AL31: 77656.755 | AM31: 0 | AN31: 471120 | AO31: Supermercati | AP31: 0 | AQ31: 73633.384 | AR31: 97194.408 | AS31: 24780.912 | AT31: 191197.59 | AU31: 15000 | AV31: 220620.12 | AW31: 2631.713 | AX31: 1472.386
A32: 34. | B32: SUPERMERCATI TOSANO CEREA S.R.L. | C32: 01286680234 | D32: 45291 | E32: Dettagliato | F32: 1430571.6 | G32: 1418860.1 | H32: -1427.359 | I32: 1089893.7 | J32: -37702.227 | K32: 111843 | L32: 132961.78 | M32: 3808.74 | N32: 26942.495 | O32: 30872.979 | P32: 0 | Q32: 0 | R32: -10482.091 | S32: 0 | T32: 0 | U32: 13059.817 | V32: 48409.204 | W32: 3485 | X32: 18.197679 | Y32: 39.995527 | Z32: 49.547363 | AA32: 57.8563 | AB32: 1006898.8 | AC32: 71148.26 | AD32: 0 | AE32: 325964.18 | AF32: 0 | AG32: 400558.25 | AH32: 276521.47 | AI32: 0 | AJ32: 440685.91 | AK32: 278762.19 | AL32: 60106.157 | AM32: 0 | AN32: 471100 | AO32: Commercio al dettaglio in esercizi non specializzati con prevalenza di prodotti alimentari e bevande | AP32: 0 | AQ32: 24715.53 | AR32: 430910.37 | AS32: 31154.501 | AT32: 114655.44 | AU32: 0 | AV32: 597443.69 | AW32: 6188.529 | AX32: 19392.582 | AY32: 65137.781
A33: 35. | B33: PENNY MARKET S.R.L. | C33: 12619750156 | D33: 45291 | E33: Dettagliato | F33: 1543201.5 | G33: 1459033.3 | H33: 0 | I33: 1126355.3 | J33: -6595.698 | K33: 154834.78 | L33: 151886.7 | M33: 8640.149 | N33: 87497.612 | O33: 48860.117 | P33: 911.345 | Q33: 0 | R33: -5541.848 | S33: 8701.262 | T33: 0 | U33: -9309.64 | V33: -16719.713 | W33: 4483 | X33: 8.8454562 | Y33: 18.872335 | Z33: 24.099031 | AA33: -534.95955 | AB33: 572172.6 | AC33: 4923.246 | AD33: 0 | AE33: 108331.24 | AF33: 0 | AG33: 115081.04 | AH33: 228594.99 | AI33: 0 | AJ33: 444553.7 | AK33: 0 | AL33: 17143.074 | AM33: 0 | AN33: 471120 | AO33: Supermercati | AP33: 0 | AQ33: 69522.859 | AR33: 74002.126 | AS33: 263138.84 | AT33: 35549.572 | AU33: 0 | AV33: 444553.7 | AW33: 859.115 | AX33: 4484.893 | AY33: -4522.57
A34: 36. | B34: AGORA' NETWORK SOCIETA' CONSORTILE A R.L. | C34: 13211090157 | D34: 45291 | E34: Dettagliato | F34: 1390461.8 | G34: 1348280.4 | H34: 0 | I34: 1318454.3 | J34: -20463.202 | K34: 100084.55 | L34: 3887.151 | M34: 454.168 | N34: 580.098 | O34: 799.378 | P34: 0 | Q34: 0 | R34: 13530.377 | S34: 0 | T34: 0 | U34: 11.832 | V34: 183.889 | W34: 49 | X34: 16.602503 | Y34: 29.937058 | Z34: 61.84138 | AA34: 49.792434 | AB34: 333359.94 | AC34: 178999.94 | AD34: 0 | AE34: 131856.51 | AF34: 0 | AG34: 18479.802 | AH34: 164594.22 | AI34: 0 | AJ34: 257361.71 | AK34: 89414.116 | AL34: 1304.38 | AM34: 0 | AN34: 461904 | AO34: Gruppi di acquisto; mandatari agli acquisti; buyer | AP34: 0 | AQ34: 1213.321 | AR34: 4551.34 | AS34: 208.886 | AT34: 194041.4 | AU34: 0 | AV34: 313477.71 | AW34: 56.326 | AX34: 184.108 | AY34: -8368.432
A35: 37. | B35: IN'S MERCATO S.P.A. | C35: 02896940273 | D35: 45291 | E35: Dettagliato | F35: 1404190.9 | G35: 1393094.5 | H35: 0 | I35: 1011551.2 | J35: 5937.781 | K35: 115062.45 | L35: 113492.44 | M35: 10239.466 | N35: 56890.814 | O35: 48271.895 | P35: 950 | Q35: 1659.118 | R35: -348.95 | S35: 0 | T35: 0 | U35: 10396.178 | V35: 29390.581 | W35: 3886 | X35: 16.146717 | Y35: 34.728854 | Z35: 74.549959 | AA35: 107.17246 | AB35: 546428.13 | AC35: 4692.442 | AD35: 0 | AE35: 85973.854 | AF35: 0 | AG35: 199867.04 | AH35: 272988.32 | AI35: 0 | AJ35: 303275.77 | AK35: 35792.576 | AL35: 42037.216 | AM35: 10719.522 | AN35: 471130 | AO35: Discount di alimentari | AP35: 0 | AQ35: 173686.31 | AR35: 216160.48 | AS35: 3012.807 | AT35: 13267.007 | AU35: 10719.522 | AV35: 328100.04 | AW35: 5335.953 | AX35: 1570.935 | AY35: 42673.435
A36: 38. | B36: CONAD CENTRO NORD SOCIETA' COOPERATIVA | C36: 01751820356 | D36: 45291 | E36: Dettagliato | F36: 1564045.7 | G36: 1350867.3 | H36: 0 | I36: 1378249.8 | J36: -7694.86 | K36: 83039.306 | L36: 13368.226 | M36: 13054.62 | N36: 26698.634 | O36: 15532.585 | P36: 0 | Q36: 5943.633 | R36: 121.44 | S36: -2886.778 | T36: 0 | U36: 3492.478 | V36: 29596.021 | W36: 184 | X36: 6.9279277 | Y36: 13.729253 | Z36: 51.26353 | AA36: 10.338238 | AB36: 763451.31 | AC36: 66814.362 | AD36: 0 | AE36: 59928.236 | AF36: 0 | AG36: 351566.4 | AH36: 239529.71 | AI36: 0 | AJ36: 321854.76 | AK36: 99112.704 | AL36: 29445.076 | AM36: 0 | AN36: 461904 | AO36: Gruppi di acquisto; mandatari agli acquisti; buyer | AP36: 9417.687 | AQ36: 17383.145 | AR36: 284437.13 | AS36: 167080.86 | AT36: 183491.31 | AU36: 759.914 | AV36: 399198.74 | AW36: 1221.55 | AX36: 11507.957 | AY36: 46571.726
A37: 39. | B37: ALI' S.P.A. | C37: 00348980285 | D37: 45291 | E37: Dettagliato | F37: 1359569 | G37: 1348522.5 | H37: 0 | I37: 985872.35 | J37: -9340.974 | K37: 69962.487 | L37: 180407.79 | M37: 7129.962 | N37: 6352.147 | O37: 43541.772 | P37: 0 | Q37: 12141.358 | R37: 3650.062 | S37: -3283.328 | T37: 0 | U37: 15302.644 | V37: 48566.21 | W37: 4689 | X37: 9.2359723 | Y37: 16.027266 | Z37: 26.588238 | AA37: 33.033246 | AB37: 1085832 | AC37: 25149.3 | AD37: 0 | AE37: 109526.75 | AF37: 0 | AG37: 852090.41 | AH37: 147440.32 | AI37: 0 | AJ37: 202002.36 | AK37: 6.903 | AL37: 64561.189 | AM37: 0 | AN37: 471120 | AO37: Supermercati | AP37: 0 | AQ37: 2132.577 | AR37: 589016.81 | AS37: 1972.418 | AT37: 147051.96 | AU37: 169382.63 | AV37: 202055.51 | AW37: 3398.32 | AX37: 2187.678 | AY37: 80464.016
A38: 40. | B38: DIMAR S.P.A. | C38: 00294760046 | D38: 45291 | E38: Dettagliato | F38: 1346959.5 | G38: 1332694.6 | H38: 0 | I38: 967660.4 | J38: -6973.323 | K38: 119545.52 | L38: 119708.53 | M38: 6075.349 | N38: 11325.256 | O38: 64773.382 | P38: 1332.901 | Q38: 499.977 | R38: -214.43 | S38: 0 | T38: 0 | U38: 16675.342 | V38: 46121.72 | W38: 4331 | X38: 10.948423 | Y38: 18.813306 | Z38: 26.954541 | AA38: 60.721891 | AB38: 1001025.6 | AC38: 26768.002 | AD38: 0 | AE38: 107864.51 | AF38: 0 | AG38: 735437.96 | AH38: 138783.93 | AI38: 0 | AJ38: 238343.88 | AK38: 20059.195 | AL38: 69357.038 | AM38: 0 | AN38: 469000 | AO38: Commercio all'ingrosso non specializzato | AP38: 0 | AQ38: 15570.123 | AR38: 654412.82 | AS38: 78146.778 | AT38: 42796.847 | AU38: 20663.186 | AV38: 248901.05 | AW38: 7468.078 | AX38: 12214.284 | AY38: 79506.826
A39: 42. | B39: TIGROS REAL ESTATE S.P.A. | C39: 12790620152 | D39: 45291 | E39: Dettagliato | F39: 1245159.4 | G39: 1187345.1 | H39: -1337.248 | I39: 914433.67 | J39: -2602.132 | K39: 73961.314 | L39: 118415.77 | M39: 13862.375 | N39: 17666.07 | O39: 39613.786 | P39: 27.868 | Q39: 0 | R39: 3085.883 | S39: -1128.034 | T39: 0 | U39: 19104.7 | V39: 52633.834 | W39: 3391 | X39: 18.345907 | Y39: 34.183513 | Z39: 74.131542 | AA39: 112.67158 | AB39: 571787.8 | AC39: 43966.163 | AD39: 0 | AE39: 47648.964 | AF39: 0 | AG39: 366390.4 | AH39: 132115.41 | AI39: 0 | AJ39: 183048.74 | AK39: 29565.684 | AL39: 86302.312 | AM39: 15302.138 | AN39: 682001 | AO39: Locazione immobiliare di beni propri | AP39: 0 | AQ39: 19237.944 | AR39: 270890.7 | AS39: 27382.028 | AT39: 66447.806 | AU39: 47446.517 | AV39: 199345.77 | AW39: 3156.01 | AX39: 6431.536 | AY39: 51438.219
A40: 43. | B40: BUNGE ITALIA S.P.A. | C40: 01532980388 | D40: 45291 | E40: Dettagliato | F40: 1265540.1 | G40: 1282848.9 | H40: -27752.793 | I40: 1125735.2 | J40: -29196.921 | K40: 111534.79 | L40: 11136.28 | M40: 5232.543 | N40: 1503.762 | O40: 10167.356 | P40: 1030.48 | Q40: 0 | R40: -12158.069 | S40: 26337.658 | T40: 0 | U40: 2673.866 | V40: 39902.33 | W40: 157 | X40: 6.4799422 | Y40: 34.328217 | Z40: 80.314321 | AA40: -227.27618 | AB40: 396588.79 | AC40: 36172.231 | AD40: 0 | AE40: 169743.38 | AF40: 0 | AG40: 92316.115 | AH40: 41651.924 | AI40: 0 | AJ40: 250048.51 | AK40: 37735.727 | AL40: 20.077 | AM40: 0 | AN40: 104120 | AO40: Produzione di olio raffinato o grezzo da semi oleosi o frutti oleosi prevalentemente non di produzione propria | AP40: 0 | AQ40: 342.612 | AR40: 78120.929 | AS40: 2950.005 | AT40: 55109.171 | AU40: 89482.193 | AV40: 250048.51 | AW40: 0 | AX40: 820.425 | AY40: -30299.435
A41: 44. | B41: COCA-COLA HBC ITALIA S.R.L. | C41: 12363410155 | D41: 45291 | E41: Dettagliato | F41: 1326233.5 | G41: 1273920.7 | H41: -3543.748 | I41: 734969.93 | J41: 4586.243 | K41: 243057.77 | L41: 153016.33 | M41: 7187.289 | N41: 23101.191 | O41: 34040.175 | P41: 0 | Q41: 0 | R41: 133641.08 | S41: 1561.488 | T41: 0 | U41: 41257.903 | V41: 220219.27 | W41: 2001 | X41: 10.966221 | Y41: 36.030205 | Z41: 35.806324 | AA41: 55.37752 | AB41: 1780839.7 | AC41: 250773.79 | AD41: 0 | AE41: 83872.939 | AF41: 1800 | AG41: 987779.92 | AH41: 167899.9 | AI41: 0 | AJ41: 755545.32 | AK41: 0 | AL41: 510.087 | AM41: 88547.579 | AN41: 110700 | AO41: Industria delle bibite analcoliche, delle acque minerali e di altre acque in bottiglia | AP41: 0 | AQ41: 35461.174 | AR41: 274243.81 | AS41: 1011321.7 | AT41: 280872.92 | AU41: 91081.568 | AV41: 755545.32 | AW41: 6298.201 | AX41: 1675.526 | AY41: 103177.59
A42: 45. | B42: CONAD ADRIATICO SOCIETA' COOPERATIVA | C42: 00105820443 | D42: 45291 | E42: Dettagliato | F42: 1343059 | G42: 1194099.3 | H42: 0 | I42: 1197196.3 | J42: -2298.573 | K42: 84016.371 | L42: 12657.292 | M42: 3211.865 | N42: 5701.301 | O42: 4479.656 | P42: 0 | Q42: 685.428 | R42: 4375.716 | S42: -1000 | T42: 0 | U42: 5739.185 | V42: 35045.927 | W42: 339 | X42: 7.8274911 | Y42: 15.955451 | Z42: 50.133546 | AA42: 87.235372 | AB42: 575588.24 | AC42: 102629.32 | AD42: 0 | AE42: 47991.615 | AF42: 0 | AG42: 285871.77 | AH42: 179243.53 | AI42: 0 | AJ42: 198316.52 | AK42: 91387.614 | AL42: 1668.063 | AM42: 126638.44 | AN42: 463920 | AO42: Commercio all'ingrosso non specializzato di prodotti alimentari, bevande e tabacco | AP42: 443.266 | AQ42: 3690.623 | AR42: 7023.007 | AS42: 213337.69 | AT42: 172521.15 | AU42: 126638.44 | AV42: 283926.79 | AW42: 723.788 | AX42: 2274.39 | AY42: 22372.403
A43: 46. | B43: GRANAROLO S.P.A. IN SIGLA G. SPA | C43: 04119190371 | D43: 45291 | E43: Dettagliato | F43: 1207872 | G43: 1172535 | H43: 27463 | I43: 846101 | J43: 1457 | K43: 200625 | L43: 88883 | M43: 7183 | N43: 6485 | O43: 43638 | P43: 0 | Q43: 156 | R43: -10685 | S43: 0 | T43: 0 | U43: -5053 | V43: 7712 | W43: 1272 | X43: 10.524232 | Y43: 26.383167 | Z43: 23.200771 | AA43: 11.432259 | AB43: 1339820 | AC43: 56970 | AD43: 0 | AE43: 124596 | AF43: 0 | AG43: 350640 | AH43: 315328 | AI43: 0 | AJ43: 640885 | AK43: 497433 | AL43: 130704 | AM43: 0 | AN43: 105110 | AO43: Trattamento igienico del latte | AP43: 0 | AQ43: 113182 | AR43: 353587 | AS43: 214002 | AT43: 403749 | AU43: 0 | AV43: 961452 | AW43: 9167 | AX43: 0 | AY43: 51136
... A59: 63. | B59: UNIGRA' S.P.A. | C59: 02403240399 | D59: 45291 | E59: Dettagliato | F59: 1009075.5 | G59: 947278.88 | H59: -38060.845 | I59: 653476.53 | J59: 3923.232 | K59: 194657.87 | L59: 46660.209 | M59: 7518.604 | N59: 8763.482 | O59: 19467.334 | P59: 121.909 | Q59: 25000 | R59: -14041.747 | S59: -6062.447 | T59: 0 | U59: 9444.057 | V59: 19938.055 | W59: 738 | X59: -8.5950046 | Y59: 33.426357 | Z59: 78.745414 | AA59: -0.11412463 | AB59: 916935.96 | AC59: 97757.403 | AD59: 616.432 | AE59: 197132.83 | AF59: 0 | AG59: 394483.03 | AH59: 154342.43 | AI59: 0 | AJ59: 392927.99 | AK59: 302241.35 | AL59: 81419.398 | AM59: 0 | AN59: 104120 | AO59: Produzione di olio raffinato o grezzo da semi oleosi o frutti oleosi prevalentemente non di produzione propria | AP59: 0 | AQ59: 36134.789 | AR59: 148350.39 | AS59: 257603.16 | AT59: 187621.7 | AU59: 4875.736 | AV59: 485486.82 | AW59: 2605.586 | AX59: 3797.96 | AY59: 69032.423
A60: 64. | B60: NESTLE' ITALIANA S.P.A. IN FORMA ABBREVIATA NE.IT. S.P.A. | C60: 00777280157 | D60: 45291 | E60: Dettagliato | F60: 972013 | G60: 971754 | H60: 0 | I60: 475580 | J60: 0 | K60: 280567 | L60: 132370 | M60: 9989 | N60: 0 | O60: 25605 | P60: 573 | Q60: 0 | R60: 14434 | S60: 0 | T60: 15617 | U60: 11793 | V60: 65587 | W60: 2005 | X60: 7.4844484 | Y60: 15.40994 | Z60: 0 | AA60: 0 | AB60: 627703 | AC60: 167742 | AD60: 0 | AE60: 73106 | AF60: 0 | AG60: 116306 | AH60: 231734 | AI60: 0 | AJ60: 404558 | AK60: 26688 | AL60: 3 | AM60: 0 | AN60: 100000 | AO60: Industrie alimentari | AP60: 0 | AQ60: 13166 | AR60: 138152 | AS60: 90161 | AT60: 313115 | AU60: 0 | AV60: 491189 | AW60: 1040 | AX60: 0
A61: 65. | B61: BIG S.R.L. | C61: 04492200961 | D61: 45291 | E61: Dettagliato | F61: 905827 | G61: 904542 | H61: 0 | I61: 667341 | J61: 3118 | K61: 144736 | L61: 52080 | M61: 583 | N61: 912 | O61: 9311 | P61: 0 | Q61: 0 | R61: 4638 | S61: 0 | T61: 0 | U61: 7649 | V61: 24735 | W61: 807 | X61: 5.5690485 | Y61: 17.250668 | Z61: 15.755002 | AA61: -8.2020412 | AB61: 740472 | AC61: 37613 | AD61: 0 | AE61: 23179 | AF61: 0 | AG61: 463244 | AH61: 34357 | AI61: 0 | AJ61: 223443 | AK61: 140630 | AL61: 3286 | AM61: 194564 | AN61: 463310 | AO61: Commercio all'ingrosso di prodotti lattiero-caseari e di uova | AP61: 0 | AQ61: 313680 | AR61: 50879 | AS61: 88 | AT61: 60955 | AU61: 288368 | AV61: 262761 | AW61: 0 | AX61: 37 | AY61: 40368
A62: 66. | B62: SALUMIFICI GRANTERRE S.P.A. | C62: 02654810361 | D62: 45291 | E62: Dettagliato | F62: 896178 | G62: 865693 | H62: 8076 | I62: 618523 | J62: -108 | K62: 137147 | L62: 91358 | M62: 4097 | N62: 1826 | O62: 27621 | P62: 0 | Q62: 294 | R62: -15677 | S62: 847 | T62: 760 | U62: -1662 | V62: 3012 | W62: 1403 | X62: 10.05029 | Y62: 22.557953 | Z62: 31.325385 | AA62: 21.440664 | AB62: 726189 | AC62: 33693 | AD62: 0 | AE62: 160707 | AF62: 0 | AG62: 166717 | AH62: 216664 | AI62: 0 | AJ62: 452611 | AK62: 259889 | AL62: 131899 | AM62: 0 | AN62: 101300 | AO62: Produzione di prodotti a base di carne (inclusa la carne di volatili) | AP62: 0 | AQ62: 129214 | AR62: 209161 | AS62: 4483 | AT62: 88062 | AU62: 821 | AV62: 542915 | AW62: 3081 | AX62: 1842 | AY62: 35442
A63: 67. | B63: CONSERVE ITALIA - CONSORZIO ITALIANO FRA COOPERATIVE AGRICOLE - S OCIETA' COOPERATIVA AGRICOLA - IN FORMA ABBREVIATA CONSERVE ITALIA SOC.COOP. AG RICOLA . | C63: 00708311204 | D63: 45107 | E63: Dettagliato | F63: 863870.24 | G63: 836755.27 | H63: -454.27 | I63: 479932.72 | J63: -5759.907 | K63: 244926.71 | L63: 79653.979 | M63: 2835.061 | N63: 10949.06 | O63: 30829.366 | P63: 280 | Q63: 0 | R63: -13543.036 | S63: 0 | T63: 0 | U63: 12.309 | V63: 6667.899 | W63: 2144 | X63: 19.568423 | Y63: 33.736204 | Z63: 32.534358 | AA63: 85.932508 | AB63: 874850.98 | AC63: 64345.526 | AD63: 0 | AE63: 196346.83 | AF63: 0 | AG63: 293481.61 | AH63: 223755.3 | AI63: 0 | AJ63: 432549.75 | AK63: 211009.58 | AL63: 115897.07 | AM63: 0 | AN63: 103000 | AO63: Lavorazione e conservazone di frutta e ortaggi | AP63: 361.5 | AQ63: 50150.658 | AR63: 298649.9 | AS63: 107299.38 | AT63: 104021.27 | AU63: 0 | AV63: 547761.54 | AW63: 10277.3 | AX63: 2124.367 | AY63: 27457.603
A64: 68. | B64: UNICOOP ETRURIA SOCIETA' COOPERATIVA | C64: 00103530499 | D64: 45291 | E64: Dettagliato | F64: 937600.55 | G64: 919095.14 | H64: 0 | I64: 653266.67 | J64: 4100.076 | K64: 95093.082 | L64: 119402.2 | M64: 15888.135 | N64: 20389.148 | O64: 21318.79 | P64: 155.8 | Q64: 952.358 | R64: 1156.28 | S64: -7248.932 | T64: 0 | U64: -151.672 | V64: 1093.306 | W64: 3268 | X64: 0.61991248 | Y64: 4.5550237 | Z64: 1.7720036 | AA64: 356.00226 | AB64: 1312192.5 | AC64: 64314.136 | AD64: 844.133 | AE64: 45160.175 | AF64: 0 | AG64: 272829.89 | AH64: 150386.39 | AI64: 388.022 | AJ64: 895446.91 | AK64: 783112.83 | AL64: 20892.872 | AM64: 801.557 | AN64: 471100 | AO64: Commercio al dettaglio in esercizi non specializzati con prevalenza di prodotti alimentari e bevande | AP64: 0 | AQ64: 148902.24 | AR64: 444414.41 | AS64: 455430.18 | AT64: 130744.63 | AU64: 63308.729 | AV64: 995056.11 | AW64: 8355.779 | AX64: 3339.294 | AY64: 6217.749
A65: 69. | B65: FERRERO INDUSTRIALE ITALIA S.R.L. | C65: 03629080049 | D65: 45169 | E65: Dettagliato | F65: 869727 | G65: 805718 | H65: 0 | I65: 62200 | J65: 0 | K65: 324331 | L65: 276367 | M65: 5153 | N65: 682 | O65: 120428 | P65: 8608 | Q65: 0 | R65: -4875 | S65: 0 | T65: 0 | U65: 10588 | V65: 56495 | W65: 5330 | X65: 7.6686653 | Y65: 20.256597 | Z65: 29.440096 | AA65: 26.124153 | AB65: 1401204 | AC65: 1476 | AD65: 0 | AE65: 26125 | AF65: 0 | AG65: 856076 | AH65: 123286 | AI65: 0 | AJ65: 494540 | AK65: 16976 | AL65: 54 | AM65: 0 | AN65: 108200 | AO65: Produzione di cacao in polvere, cioccolato, caramelle e confetterie | AP65: 0 | AQ65: 88 | AR65: 1122619 | AS65: 113 | AT65: 234068 | AU65: 0 | AV65: 505900 | AW65: 10017 | AX65: 18137 | AY65: 152537
A66: 70. | B66: AVI.COOP SOCIETA' COOPERATIVA AGRICOLA IN BREVE: AVI.COOP S.C.A. OVVERO: AVI.COOP SOC. COOP. AGR. | C66: 01247140401 | D66: 45291 | E66: Dettagliato | F66: 837376.46 | G66: 827415.52 | H66: -1490.023 | I66: 625295.4 | J66: -1359.124 | K66: 58830.671 | L66: 127227.82 | M66: 578.856 | N66: 8657.432 | O66: 12883.658 | P66: 0 | Q66: 0 | R66: -5205.937 | S66: 0 | T66: 0 | U66: 0.603 | V66: 55.205 | W66: 5481 | X66: -2.2380724 | Y66: 27.526003 | Z66: 69.549139 | AA66: 141.02484 | AB66: 206571.24 | AC66: 43877.561 | AD66: 0 | AE66: 13121.923 | AF66: 0 | AG66: 8335.069 | AH66: 39869.184 | AI66: 0 | AJ66: 179487.08 | AK66: 0.022 | AL66: 11.353 | AM66: 0 | AN66: 016300 | AO66: Attività che seguono la raccolta | AP66: 0 | AQ66: 1004.733 | AR66: 126312.04 | AS66: 12327.736 | AT66: 52125.444 | AU66: 0 | AV66: 179487.08 | AW66: 9583.425 | AX66: 1668.011 | AY66: 7528.437
A67: 71. | B67: HEINEKEN ITALIA SPA | C67: 00610140071 | D67: 45291 | E67: Dettagliato | F67: 855632 | G67: 826616 | H67: -17483 | I67: 390614 | J67: 0 | K67: 202318 | L67: 84919 | M67: 8713 | N67: 0 | O67: 35256 | P67: 1105 | Q67: 0 | R67: -5895 | S67: 0 | T67: 0 | U67: 35273 | V67: 91539 | W67: 1102 | X67: 9.716913 | Y67: 21.771591 | Z67: 32.10384 | AA67: 20.484771 | AB67: 710098 | AC67: 20253 | AD67: 0 | AE67: 78751 | AF67: 0 | AG67: 236362 | AH67: 136497 | AI67: 0 | AJ67: 267207 | AK67: 25287 | AL67: 6063 | AM67: 158592 | AN67: 110500 | AO67: Produzione di birra | AP67: 0 | AQ67: 4127 | AR67: 228525 | AS67: 140755 | AT67: 92622 | AU67: 158592 | AV67: 455762 | AW67: 1932 | AX67: 663 | AY67: 139406
A68: 72. | B68: MAIORA SOCIETA' PER AZIONI | C68: 07390770720 | D68: 45291 | E68: Dettagliato | F68: 832391 | G68: 825297 | H68: 0 | I68: 635633 | J68: -1025 | K68: 61351 | L68: 71944 | M68: 4738 | N68: 5629 | O68: 25780 | P68: 0 | Q68: 0 | R68: -1129 | S68: 0 | T68: -658 | U68: 6907 | V68: 19647 | W68: 2626 | X68: 7.3652043 | Y68: 15.09985 | Z68: 38.051547 | AA68: 52.226254 | AB68: 370350 | AC68: 26076 | AD68: 0 | AE68: 65590 | AF68: 0 | AG68: 89314 | AH68: 134606 | AI68: 0 | AJ68: 179216 | AK68: 93035 | AL68: 46818 | AM68: 0 | AN68: 469000 | AO68: Commercio all'ingrosso non specializzato | AP68: 0 | AQ68: 76437 | AR68: 129674 | AS68: 2561 | AT68: 41651 | AU68: 0 | AV68: 264819 | AW68: 11551 | AX68: 7619 | AY68: 35553
A69: 74. | B69: CASEIFICI GRANTERRE SPA | C69: 01299680353 | D69: 45291 | E69: Dettagliato | F69: 731727 | G69: 727439 | H69: -1191 | I69: 617968 | J69: -1212 | K69: 50264 | L69: 33391 | M69: 927 | N69: 412 | O69: 8894 | P69: 170 | Q69: 0 | R69: -11148 | S69: 0 | T69: 20 | U69: 3173 | V69: 6612 | W69: 532 | X69: 5.370508 | Y69: 19.087135 | Z69: 78.039032 | AA69: 59.583467 | AB69: 522573 | AC69: 122683 | AD69: 0 | AE69: 251054 | AF69: 0 | AG69: 53989 | AH69: 174078 | AI69: 0 | AJ69: 373112 | AK69: 271712 | AL69: 57481 | AM69: 0 | AN69: 463310 | AO69: Commercio all'ingrosso di prodotti lattiero-caseari e di uova | AP69: 0 | AQ69: 4158 | AR69: 56885 | AS69: 957 | AT69: 151139 | AU69: 0 | AV69: 460446 | AW69: 2020 | AX69: 899 | AY69: 18678
A70: 75. | B70: COOP LIGURIA SOCIETA' COOPERATIVA DI CONSUMO | C70: 00103220091 | D70: 45291 | E70: Dettagliato | F70: 834708.63 | G70: 820690.63 | H70: 0 | I70: 597251.65 | J70: -54.94 | K70: 86106.216 | L70: 92148.29 | M70: 6352.886 | N70: 34685.215 | O70: 14516.798 | P70: 0 | Q70: 4037.502 | R70: 30912.419 | S70: -17796.118 | T70: 0 | U70: 2396.1 | V70: 10385.21 | W70: 2732 | X70: 3.4362661 | Y70: 9.3962829 | Z70: 8.3881136 | AA70: 342.59959 | AB70: 1658098.9 | AC70: 5459.738 | AD70: 0 | AE70: 36556.039 | AF70: 0 | AG70: 779190.74 | AH70: 18449.788 | AI70: 0 | AJ70: 768947.36 | AK70: 759495.97 | AL70: 51877.609 | AM70: 0 | AN70: 471120 | AO70: Supermercati | AP70: 0 | AQ70: 8077.117 | AR70: 40800.098 | AS70: 452084.97 | AT70: 414349.91 | AU70: 647647.59 | AV70: 846504.09 | AW70: 2350.744 | AX70: 6705.617 | AY70: 3204.207
A71: 76. | B71: APULIA DISTRIBUZIONE S.R.L. | C71: 05754810728 | D71: 45291 | E71: Dettagliato | F71: 819823.19 | G71: 805167.71 | H71: 0 | I71: 722819.08 | J71: -4676.139 | K71: 48057.989 | L71: 13321.443 | M71: 13421.738 | N71: 9835.529 | O71: 5916.234 | P71: 1273.378 | Q71: 0 | R71: -119.677 | S71: -249.998 | T71: 0 | U71: 8922.328 | V71: 561.937 | W71: 327 | X71: 0.08254394 | Y71: 27.243624 | Z71: 33.311329 | AA71: -18.825017 | AB71: 331965.48 | AC71: 83134.287 | AD71: 0 | AE71: 53048.793 | AF71: 0 | AG71: 118345.15 | AH71: 141041.51 | AI71: 0 | AJ71: 170256.78 | AK71: 37840.606 | AL71: 45474.118 | AM71: 0 | AN71: 463920 | AO71: Commercio all'ingrosso non specializzato di prodotti alimentari, bevande e tabacco | AP71: 0 | AQ71: 10625.087 | AR71: 53216.805 | AS71: 4549.059 | AT71: 131540.52 | AU71: 31555.438 | AV71: 207667.29 | AW71: 2018.209 | AX71: 1955.662 | AY71: 19427.382
...

Sheet calcoli
A1: Gruppo | B1: Ragione sociale | C1: P.Iva | D1: Anno | E1: Tipo di bilancio | F1: Classe | G1: Sottoclasse | H1: Nota Generale | I1: Fatturato | L1: Fatturato (100%) +/- Δ Rimanenze Prodotti | O1: Consumo di Materie Prime | R1: margine commerciale PURO | U1: Altri ricavi | X1: Margine Commerciale/I0USTRIALE | AA1: Spese per Servizi | AD1: Costo del lavoro | AG1: +/- Altri Costi e Ricavi Operativi | AJ1: EBITDAR | AM1: Spese per affitti e noleggi | AP1: EBITDA margin | AS1: Ammortamenti e Svalutazioni | AV1: EBIT margin | AY1: Gestione finanziaria (interessi e rettifiche) | BB1: Gestione straordinaria | BE1: Imposte | BH1: Profit margin | BK1: Crescita Fatturato ultimo anno | BL1: Crescita Fatturato a 3 anni | BM1: Crescita Fatturato a 5 anni | BN1: crescita EBITDA 5 anni | BO1: Risultato d'Esercizio / Ricavi | BP1: ROI | BQ1: ROE | BR1: Profit Margin | BS1: Rotazione Attivo | BT1: Leva Finanziaria | BU1: Tempi medi giacenza Scorte (rimanenze/Fatturato)*360 | BV1: Tempi medi incasso (Clienti/Fatturato)*360 | BW1: Tempi medi pagamento (Fornitori/(Acquisti+Servizi+Affitti e noleggi))*360 | BX1: mezzi propri/attivo | BY1: debiti finanziari netti/ricavi | BZ1: Debiti a breve/ricavi | CA1: Aggregato | CB1: Crediti vs Soci | CC1: % | CD1: Immobilizzi immateriali | CE1: % | CF1: Immobilizzi materiali | CG1: % | CH1: Immobilizzi finanziari | CI1: % | CJ1: Totale Attivo Immobilizzato | CK1: % | CL1: Rimanenze | CM1: % | CN1: Crediti | CO1: % | CP1: Attività Finanziarie correnti | CQ1: % | CR1: Disponibilità Liquide | CS1: % | CT1: Totale Attivo Corrente | CU1: % | CV1: Ratei e Risconti Attivi | CW1: % | CX1: Totale Attivo | CY1: % | CZ1: Patrimonio Netto | DA1: % | DB1: Fondo TFR e Fondi Rischi | DC1: % | DD1: Debiti | DE1: % | DF1: di cui a breve termine | DG1: % | DH1: di cui a medio lungo termine | DI1: % | DJ1: Ratei e Risconti Passivi | DK1: % | DL1: Totale Passivo | DM1: %
I2: Valore | J2: % | K2: Nota | L2: Valore | M2: % | N2: Nota | O2: Valore | P2: % | Q2: Nota | R2: Valore | S2: % | T2: Nota | U2: Valore | V2: % | W2: Nota | X2: Valore | Y2: % | Z2: Nota | AA2: Valore | AB2: % | AC2: Nota | AD2: Valore | AE2: % | AF2: Nota | AG2: Valore | AH2: % | AI2: Nota | AJ2: Valore | AK2: % | AL2: Nota | AM2: Valore | AN2: % | AO2: Nota | AP2: Valore | AQ2: % | AR2: Nota | AS2: Valore | AT2: % | AU2: Nota | AV2: Valore | AW2: % | AX2: Nota | AY2: Valore | AZ2: % | BA2: Nota | BB2: Valore | BC2: % | BD2: Nota | BE2: Valore | BF2: % | BG2: Nota | BH2: Valore | BI2: % | BJ2: Nota
B3: =+Risultati!B2 -> ESSELUNGA SPA | C3: =+Risultati!C2 -> 04916380159 | D3: =IF(YEAR(Risultati!D2)=1900,(MID(Risultati!$AP$1,29,4)),YEAR(Risultati!D2)) -> 2023 | E3: =+Risultati!E2 -> Dettagliato | F3: =(LEFT(Risultati!AN2,2)&"-")&VLOOKUP((LEFT(Risultati!AN2,2)),ateco!$B$4:$C$93,2,FALSE) -> 47-Commercio al dettaglio (escluso quello di autoveicoli e di motocicli) | G3: =SUBSTITUTE((Risultati!AN2&"-"&Risultati!AO2),",",";") -> 471100-Commercio al dettaglio in esercizi non specializzati con prevalenza di prodotti alimentari e bevande | I3: =+Risultati!G2 -> 9038616 | J3: =IF(L3<>0,(I3/L3),"0") -> 1 | L3: =+Risultati!G2+Risultati!H2 -> 9038616 | M3: =IF(L3<>0,(L3/(L3+U3)),"0") -> 0.99100612 | O3: =+Risultati!I2+Risultati!J2 -> 6285561 | P3: =IF(L3<>0,(O3/(L3+U3)),"0") -> 0.68915743 | R3: =+L3-O3 -> 2753055 | S3: =IF(L3<>0,(R3/(L3+U3)),"0") -> 0.30184868 | U3: =+Risultati!F2-(Risultati!G2+Risultati!H2) -> 82030 | V3: =IF(L3<>0,(U3/(L3+U3)),"0") -> 0.0089938805 | X3: =+U3+R3 -> 2835085 | Y3: =IF(L3<>0,(X3/(L3+U3)),"0") -> 0.31084257 | AA3: =+Risultati!K2 -> 1015920 | AB3: =IF(L3<>0,(AA3/(L3+U3)),"0") -> 0.11138685 | AD3: =+Risultati!L2 -> 1052480 | AE3: =IF(L3<>0,(AD3/(L3+U3)),"0") -> 0.11539533 | AG3: =+Risultati!M2+Risultati!P2+Risultati!Q2 -> 122827 | AH3: =IF(L3<>0,(AG3/(L3+U3)),"0") -> 0.013466919 | AJ3: =+X3-AA3-AD3-AG3 -> 643858 | AK3: =IF(L3<>0,(AJ3/(L3+U3)),"0") -> 0.070593465 | AM3: =+Risultati!N2 -> 25090 | AN3: =IF(L3<>0,(AM3/(L3+U3)),"0") -> 0.0027509016 | AP3: =+AJ3-AM3 -> 618768 | AQ3: =IF(L3<>0,(AP3/(L3+U3)),"0") -> 0.067842563 | AS3: =+Risultati!O2 -> 406552 | AT3: =IF(L3<>0,(AS3/(L3+U3)),"0") -> 0.044574913 | AV3: =+AP3-AS3 -> 212216 | AW3: =IF(L3<>0,(AV3/(L3+U3)),"0") -> 0.02326765 | AY3: =+Risultati!R2+Risultati!S2 -> -44934 | AZ3: =IF(L3<>0,(AY3/(L3+U3)),"0") -> -0.0049266247 | BB3: =+Risultati!T2 -> 1031 | BC3: =IF(L3<>0,(BB3/(L3+U3)),"0") -> 0.00011304024 | BE3: =+Risultati!U2 -> 39284 | BF3: =IF(L3<>0,(BE3/(L3+U3)),"0") -> 0.0043071511 | BH3: =+AV3+AY3+BB3-BE3 -> 129029 | BI3: =IF(L3<>0,(+BH3/(L3+U3)),"0") -> 0.014146915 | BK3: =IF(ISNUMBER(Risultati!X2/100),(Risultati!X2/100)) -> 0.05910202 | BL3: =IF(ISNUMBER(Risultati!Y2/100),(Risultati!Y2/100)) -> 0.071247441 | BM3: =IF(ISNUMBER(Risultati!Z2/100),(Risultati!Z2/100)) -> 0.14224044 | BN3: =IF(AND(Risultati!AY2<0,calcoli!AP3<0),-IF(ISNUMBER(Risultati!AA2/100),(Risultati!AA2/100)),IF(ISNUMBER(Risultati!AA2/100),(Risultati!AA2/100))) -> -0.11973027 | BO3: =+BI3 -> 0.014146915 | BP3: =IF(Risultati!AB2>0,(AV3/Risultati!AB2),"0") -> 0.026894878 | BQ3: =IF(Risultati!AG2<>0,(BH3/Risultati!AG2),"0") -> 0.058628439 | BR3: =+BI3 -> 0.014146915 | BS3: =IF(Risultati!AB2>0,(Risultati!G2/Risultati!AB2),"0") -> 1.1454955 | BT3: =IF(Risultati!AG2<>0,(Risultati!AB2/Risultati!AG2),"0") -> 3.5853334 | BU3: =IF(AND(Risultati!G2>0,(Risultati!AE2-Risultati!AF2)>=0),((Risultati!AE2-Risultati!AF2)/Risultati!G2*360),"0") -> 22.529374 | BV3: =IF(OR(E3="abbreviato",Risultati!G2=0),"0",((Risultati!AC2+Risultati!AD2)/Risultati!G2*360)) -> 10.484216 | BW3: =IF(OR(E3="abbreviato",Risultati!G2=0,SUM(Risultati!I2+Risultati!K2+Risultati!M2)=0),"0",(((Risultati!AH2+Risultati!AI2)/(Risultati!I2+Risultati!K2+Risultati!N2)*360))) -> 83.190027 | BX3: =IF(Risultati!AB2>0,(+Risultati!AG2/Risultati!AB2),"0") -> 0.27891409 | BY3: =IF(OR(E3="abbreviato",Risultati!G2=0),"0",(((Risultati!AK2-(Risultati!AL2+Risultati!AM2))/Risultati!G2))) -> 0.32164758 | BZ3: =IF(Risultati!G2>0,(Risultati!AJ2/Risultati!G2),"0") -> 0.26104417 | CB3: =+Risultati!AP2 -> 0 | CC3: =IF($CX3>0,(CB3/$CX3),"0") -> 0 | CD3: =+Risultati!AQ2 -> 220145 | CE3: =IF($CX3>0,(CD3/$CX3),"0") -> 0.027899748 | CF3: =+Risultati!AR2 -> 5222483 | CG3: =IF($CX3>0,(CF3/$CX3),"0") -> 0.66186359 | CH3: =+Risultati!AS2 -> 1159374 | CI3: =IF($CX3>0,(CH3/$CX3),"0") -> 0.14693153 | CJ3: =+CH3+CF3+CD3 -> 6602002 | CK3: =IF($CX3>0,(CJ3/$CX3),"0") -> 0.83669488 | CL3: =+Risultati!AE2+Risultati!AF2 -> 565651 | CM3: =IF($CX3>0,(CL3/$CX3),"0") -> 0.071686936 | CN3: =+Risultati!AT2 -> 402192 | CO3: =IF($CX3>0,(CN3/$CX3),"0") -> 0.050971203 | CP3: =+Risultati!AU2 -> 53307 | CQ3: =IF($CX3>0,(CP3/$CX3),"0") -> 0.0067557831 | CR3: =+Risultati!AL2 -> 252746 | CS3: =IF($CX3>0,(CR3/$CX3),"0") -> 0.032031387 | CT3: =+CR3+CP3+CN3+CL3 -> 1273896 | CU3: =IF($CX3>0,(CT3/$CX3),"0") -> 0.16144531 | CV3: =+Risultati!AX2 -> 14675 | CW3: =IF($CX3>0,(CV3/$CX3),"0") -> 0.0018598142 | CX3: =+CV3+CT3+CJ3 -> 7890573 | CY3: =IF($CX3>0,(CX3/$CX3),"0") -> 1 | CZ3: =+Risultati!AG2 -> 2200792 | DA3: =IF($CX3>0,(CZ3/$CX3),"0") -> 0.27891409 | DB3: =+DL3-CZ3-DD3-DJ3 -> 118851 | DC3: =IF($CX3>0,(DB3/$CX3),"0") -> 0.015062404 | DD3: =+Risultati!AV2 -> 5393411 | DE3: =IF($CX3>0,(DD3/$CX3),"0") -> 0.6835259 | DF3: =+Risultati!AJ2 -> 2359478 | DG3: =IF($CX3>0,(DF3/$CX3),"0") -> 0.29902493 | DH3: =+DD3-DF3 -> 3033933 | DI3: =IF($CX3>0,(DH3/$CX3),"0") -> 0.38450097 | DJ3: =+Risultati!AW2 -> 177519 | DK3: =IF($CX3>0,(DJ3/$CX3),"0") -> 0.022497606 | DL3: =+CX3 -> 7890573 | DM3: =IF($CX3>0,(DL3/$CX3),"0") -> 1
B4: =+Risultati!B3 -> LIDL ITALIA S.R.L. | C4: =+Risultati!C3 -> 02275030233 | D4: =IF(YEAR(Risultati!D3)=1900,(MID(Risultati!$AP$1,29,4)),YEAR(Risultati!D3)) -> 2024 | E4: =+Risultati!E3 -> Dettagliato | F4: =(LEFT(Risultati!AN3,2)&"-")&VLOOKUP((LEFT(Risultati!AN3,2)),ateco!$B$4:$C$93,2,FALSE) -> 46-Commercio all'ingrosso (escluso quello di autoveicoli e di motocicli) | G4: =SUBSTITUTE((Risultati!AN3&"-"&Risultati!AO3),",",";") -> 469000-Commercio all'ingrosso non specializzato | I4: =+Risultati!G3 -> 7158326 | J4: =IF(L4<>0,(I4/L4),"0") -> 1 | L4: =+Risultati!G3+Risultati!H3 -> 7158326 | M4: =IF(L4<>0,(L4/(L4+U4)),"0") -> 0.99005495 | O4: =+Risultati!I3+Risultati!J3 -> 5244243 | P4: =IF(L4<>0,(O4/(L4+U4)),"0") -> 0.72532164 | R4: =+L4-O4 -> 1914083 | S4: =IF(L4<>0,(R4/(L4+U4)),"0") -> 0.26473331 | U4: =+Risultati!F3-(Risultati!G3+Risultati!H3) -> 71905 | V4: =IF(L4<>0,(U4/(L4+U4)),"0") -> 0.0099450488 | X4: =+U4+R4 -> 1985988 | Y4: =IF(L4<>0,(X4/(L4+U4)),"0") -> 0.27467836 | AA4: =+Risultati!K3 -> 657621 | AB4: =IF(L4<>0,(AA4/(L4+U4)),"0") -> 0.090954355 | AD4: =+Risultati!L3 -> 673251 | AE4: =IF(L4<>0,(AD4/(L4+U4)),"0") -> 0.093116112 | AG4: =+Risultati!M3+Risultati!P3+Risultati!Q3 -> 49284 | AH4: =IF(L4<>0,(AG4/(L4+U4)),"0") -> 0.0068163797 | AJ4: =+X4-AA4-AD4-AG4 -> 605832 | AK4: =IF(L4<>0,(AJ4/(L4+U4)),"0") -> 0.083791514 | AM4: =+Risultati!N3 -> 84069 | AN4: =IF(L4<>0,(AM4/(L4+U4)),"0") -> 0.011627429 | AP4: =+AJ4-AM4 -> 521763 | AQ4: =IF(L4<>0,(AP4/(L4+U4)),"0") -> 0.072164084 | AS4: =+Risultati!O3 -> 226867 | AT4: =IF(L4<>0,(AS4/(L4+U4)),"0") -> 0.031377559 | AV4: =+AP4-AS4 -> 294896 | AW4: =IF(L4<>0,(AV4/(L4+U4)),"0") -> 0.040786525 | AY4: =+Risultati!R3+Risultati!S3 -> -23511 | AZ4: =IF(L4<>0,(AY4/(L4+U4)),"0") -> -0.0032517633 | BB4: =+Risultati!T3 -> 0 | BC4: =IF(L4<>0,(BB4/(L4+U4)),"0") -> 0 | BE4: =+Risultati!U3 -> 77452 | BF4: =IF(L4<>0,(BE4/(L4+U4)),"0") -> 0.010712244 | BH4: =+AV4+AY4+BB4-BE4 -> 193933 | BI4: =IF(L4<>0,(+BH4/(L4+U4)),"0") -> 0.026822518 | BK4: =IF(ISNUMBER(Risultati!X3/100),(Risultati!X3/100)) -> 0.0704756 | BL4: =IF(ISNUMBER(Risultati!Y3/100),(Risultati!Y3/100)) -> 0.21644515 | BM4: =IF(ISNUMBER(Risultati!Z3/100),(Risultati!Z3/100)) -> 0.38929638 | BN4: =IF(AND(Risultati!AY3<0,calcoli!AP4<0),-IF(ISNUMBER(Risultati!AA3/100),(Risultati!AA3/100)),IF(ISNUMBER(Risultati!AA3/100),(Risultati!AA3/100))) -> 0.37408386 | BO4: =+BI4 -> 0.026822518 | BP4: =IF(Risultati!AB3>0,(AV4/Risultati!AB3),"0") -> 0.077344841 | BQ4: =IF(Risultati!AG3<>0,(BH4/Risultati!AG3),"0") -> 0.10191321 | BR4: =+BI4 -> 0.026822518 | BS4: =IF(Risultati!AB3>0,(Risultati!G3/Risultati!AB3),"0") -> 1.877474 | BT4: =IF(Risultati!AG3<>0,(Risultati!AB3/Risultati!AG3),"0") -> 2.0036244 | BU4: =IF(AND(Risultati!G3>0,(Risultati!AE3-Risultati!AF3)>=0),((Risultati!AE3-Risultati!AF3)/Risultati!G3*360),"0") -> 22.715981 | BV4: =IF(OR(E4="abbreviato",Risultati!G3=0),"0",((Risultati!AC3+Risultati!AD3)/Risultati!G3*360)) -> 0.13950748 | BW4: =IF(OR(E4="abbreviato",Risultati!G3=0,SUM(Risultati!I3+Risultati!K3+Risultati!M3)=0),"0",(((Risultati!AH3+Risultati!AI3)/(Risultati!I3+Risultati!K3+Risultati!N3)*360))) -> 60.192601 | BX4: =IF(Risultati!AB3>0,(+Risultati!AG3/Risultati!AB3),"0") -> 0.49909553 | BY4: =IF(OR(E4="abbreviato",Risultati!G3=0),"0",(((Risultati!AK3-(Risultati!AL3+Risultati!AM3))/Risultati!G3))) -> 0.05191535 | BZ4: =IF(Risultati!G3>0,(Risultati!AJ3/Risultati!G3),"0") -> 0.20018605 | CB4: =+Risultati!AP3 -> 0 | CC4: =IF($CX4>0,(CB4/$CX4),"0") -> 0 | CD4: =+Risultati!AQ3 -> 111652 | CE4: =IF($CX4>0,(CD4/$CX4),"0") -> 0.029283904 | CF4: =+Risultati!AR3 -> 2747980 | CG4: =IF($CX4>0,(CF4/$CX4),"0") -> 0.7207357 | CH4: =+Risultati!AS3 -> 8537 | CI4: =IF($CX4>0,(CH4/$CX4),"0") -> 0.0022390704 | CJ4: =+CH4+CF4+CD4 -> 2868169 | CK4: =IF($CX4>0,(CJ4/$CX4),"0") -> 0.75225868 | CL4: =+Risultati!AE3+Risultati!AF3 -> 459478 | CM4: =IF($CX4>0,(CL4/$CX4),"0") -> 0.12051114 | CN4: =+Risultati!AT3 -> 182206 | CO4: =IF($CX4>0,(CN4/$CX4),"0") -> 0.047788692 | CP4: =+Risultati!AU3 -> 212878 | CQ4: =IF($CX4>0,(CP4/$CX4),"0") -> 0.055833294 | CR4: =+Risultati!AL3 -> 72756 | CS4: =IF($CX4>0,(CR4/$CX4),"0") -> 0.019082325 | CT4: =+CR4+CP4+CN4+CL4 -> 927318 | CU4: =IF($CX4>0,(CT4/$CX4),"0") -> 0.24321545 | CV4: =+Risultati!AX3 -> 17256 | CW4: =IF($CX4>0,(CV4/$CX4),"0") -> 0.0045258755 | CX4: =+CV4+CT4+CJ4 -> 3812743 | CY4: =IF($CX4>0,(CX4/$CX4),"0") -> 1 | CZ4: =+Risultati!AG3 -> 1902923 | DA4: =IF($CX4>0,(CZ4/$CX4),"0") -> 0.49909553 | DB4: =+DL4-CZ4-DD4-DJ4 -> 89287 | DC4: =IF($CX4>0,(DB4/$CX4),"0") -> 0.023418048 | DD4: =+Risultati!AV3 -> 1799919 | DE4: =IF($CX4>0,(DD4/$CX4),"0") -> 0.47207981 | DF4: =+Risultati!AJ3 -> 1432997 | DG4: =IF($CX4>0,(DF4/$CX4),"0") -> 0.37584411 | DH4: =+DD4-DF4 -> 366922 | DI4: =IF($CX4>0,(DH4/$CX4),"0") -> 0.096235702 | DJ4: =+Risultati!AW3 -> 20614 | DK4: =IF($CX4>0,(DJ4/$CX4),"0") -> 0.0054066062 | DL4: =+CX4 -> 3812743 | DM4: =IF($CX4>0,(DL4/$CX4),"0") -> 1
B5: =+Risultati!B4 -> A.I.A. - AGRICOLA ITALIANA ALIMENTARE - S.P.A. | C5: =+Risultati!C4 -> 00233470236 | D5: =IF(YEAR(Risultati!D4)=1900,(MID(Risultati!$AP$1,29,4)),YEAR(Risultati!D4)) -> 2023 | E5: =+Risultati!E4 -> Dettagliato | F5: =(LEFT(Risultati!AN4,2)&"-")&VLOOKUP((LEFT(Risultati!AN4,2)),ateco!$B$4:$C$93,2,FALSE) -> 46-Commercio all'ingrosso (escluso quello di autoveicoli e di motocicli) | G5: =SUBSTITUTE((Risultati!AN4&"-"&Risultati!AO4),",",";") -> 463210-Commercio all'ingrosso di carne fresca; congelata e surgelata | I5: =+Risultati!G4 -> 4712306 | J5: =IF(L5<>0,(I5/L5),"0") -> 0.99990664 | L5: =+Risultati!G4+Risultati!H4 -> 4712746 | M5: =IF(L5<>0,(L5/(L5+U5)),"0") -> 0.97883074 | O5: =+Risultati!I4+Risultati!J4 -> 4095391 | P5: =IF(L5<>0,(O5/(L5+U5)),"0") -> 0.85060697 | R5: =+L5-O5 -> 617355 | S5: =IF(L5<>0,(R5/(L5+U5)),"0") -> 0.12822377 | U5: =+Risultati!F4-(Risultati!G4+Risultati!H4) -> 101923 | V5: =IF(L5<>0,(U5/(L5+U5)),"0") -> 0.021169264 | X5: =+U5+R5 -> 719278 | Y5: =IF(L5<>0,(X5/(L5+U5)),"0") -> 0.14939303 | AA5: =+Risultati!K4 -> 442257 | AB5: =IF(L5<>0,(AA5/(L5+U5)),"0") -> 0.091856159 | AD5: =+Risultati!L4 -> 57265 | AE5: =IF(L5<>0,(AD5/(L5+U5)),"0") -> 0.01189386 | AG5: =+Risultati!M4+Risultati!P4+Risultati!Q4 -> 13255 | AH5: =IF(L5<>0,(AG5/(L5+U5)),"0") -> 0.0027530449 | AJ5: =+X5-AA5-AD5-AG5 -> 206501 | AK5: =IF(L5<>0,(AJ5/(L5+U5)),"0") -> 0.042889968 | AM5: =+Risultati!N4 -> 5091 | AN5: =IF(L5<>0,(AM5/(L5+U5)),"0") -> 0.0010573936 | AP5: =+AJ5-AM5 -> 201410 | AQ5: =IF(L5<>0,(AP5/(L5+U5)),"0") -> 0.041832575 | AS5: =+Risultati!O4 -> 94636 | AT5: =IF(L5<>0,(AS5/(L5+U5)),"0") -> 0.019655764 | AV5: =+AP5-AS5 -> 106774 | AW5: =IF(L5<>0,(AV5/(L5+U5)),"0") -> 0.02217681 | AY5: =+Risultati!R4+Risultati!S4 -> -17934 | AZ5: =IF(L5<>0,(AY5/(L5+U5)),"0") -> -0.0037248667 | BB5: =+Risultati!T4 -> 0 | BC5: =IF(L5<>0,(BB5/(L5+U5)),"0") -> 0 | BE5: =+Risultati!U4 -> 21355 | BF5: =IF(L5<>0,(BE5/(L5+U5)),"0") -> 0.0044354036 | BH5: =+AV5+AY5+BB5-BE5 -> 67485 | BI5: =IF(L5<>0,(+BH5/(L5+U5)),"0") -> 0.01401654 | BK5: =IF(ISNUMBER(Risultati!X4/100),(Risultati!X4/100)) -> 0.11802779 | BL5: =IF(ISNUMBER(Risultati!Y4/100),(Risultati!Y4/100)) -> 0.24983947 | BM5: =IF(ISNUMBER(Risultati!Z4/100),(Risultati!Z4/100)) -> 0.36766654 | BN5: =IF(AND(Risultati!AY4<0,calcoli!AP5<0),-IF(ISNUMBER(Risultati!AA4/100),(Risultati!AA4/100)),IF(ISNUMBER(Risultati!AA4/100),(Risultati!AA4/100))) -> 0.60629406 | BO5: =+BI5 -> 0.01401654 | BP5: =IF(Risultati!AB4>0,(AV5/Risultati!AB4),"0") -> 0.067714081 | BQ5: =IF(Risultati!AG4<>0,(BH5/Risultati!AG4),"0") -> 0.14182944 | BR5: =+BI5 -> 0.01401654 | BS5: =IF(Risultati!AB4>0,(Risultati!G4/Risultati!AB4),"0") -> 2.9884566 | BT5: =IF(Risultati!AG4<>0,(Risultati!AB4/Risultati!AG4),"0") -> 3.3139478 | BU5: =IF(AND(Risultati!G4>0,(Risultati!AE4-Risultati!AF4)>=0),((Risultati!AE4-Risultati!AF4)/Risultati!G4*360),"0") -> 2.1181477 | BV5: =IF(OR(E5="abbreviato",Risultati!G4=0),"0",((Risultati!AC4+Risultati!AD4)/Risultati!G4*360)) -> 30.349345 | BW5: =IF(OR(E5="abbreviato",Risultati!G4=0,SUM(Risultati!I4+Risultati!K4+Risultati!M4)=0),"0",(((Risultati!AH4+Risultati!AI4)/(Risultati!I4+Risultati!K4+Risultati!N4)*360))) -> 29.022728 | BX5: =IF(Risultati!AB4>0,(+Risultati!AG4/Risultati!AB4),"0") -> 0.30175491 | BY5: =IF(OR(E5="abbreviato",Risultati!G4=0),"0",(((Risultati!AK4-(Risultati!AL4+Risultati!AM4))/Risultati!G4))) -> 0.12010595 | BZ5: =IF(Risultati!G4>0,(Risultati!AJ4/Risultati!G4),"0") -> 0.17512212 | CB5: =+Risultati!AP4 -> 0 | CC5: =IF($CX5>0,(CB5/$CX5),"0") -> 0 | CD5: =+Risultati!AQ4 -> 150 | CE5: =IF($CX5>0,(CD5/$CX5),"0") -> 9.5127264e-05 | CF5: =+Risultati!AR4 -> 523919 | CG5: =IF($CX5>0,(CF5/$CX5),"0") -> 0.33225988 | CH5: =+Risultati!AS4 -> 275760 | CI5: =IF($CX5>0,(CH5/$CX5),"0") -> 0.17488196 | CJ5: =+CH5+CF5+CD5 -> 799829 | CK5: =IF($CX5>0,(CJ5/$CX5),"0") -> 0.50723697 | CL5: =+Risultati!AE4+Risultati!AF4 -> 27726 | CM5: =IF($CX5>0,(CL5/$CX5),"0") -> 0.017583324 | CN5: =+Risultati!AT4 -> 585927 | CO5: =IF($CX5>0,(CN5/$CX5),"0") -> 0.37158422 | CP5: =+Risultati!AU4 -> 111758 | CQ5: =IF($CX5>0,(CP5/$CX5),"0") -> 0.070874885 | CR5: =+Risultati!AL4 -> 49282 | CS5: =IF($CX5>0,(CR5/$CX5),"0") -> 0.031253746 | CT5: =+CR5+CP5+CN5+CL5 -> 774693 | CU5: =IF($CX5>0,(CT5/$CX5),"0") -> 0.49129617 | CV5: =+Risultati!AX4 -> 2313 | CW5: =IF($CX5>0,(CV5/$CX5),"0") -> 0.0014668624 | CX5: =+CV5+CT5+CJ5 -> 1576835 | CY5: =IF($CX5>0,(CX5/$CX5),"0") -> 1 | CZ5: =+Risultati!AG4 -> 475818 | DA5: =IF($CX5>0,(CZ5/$CX5),"0") -> 0.3017551 | DB5: =+DL5-CZ5-DD5-DJ5 -> 28474 | DC5: =IF($CX5>0,(DB5/$CX5),"0") -> 0.018057692 | DD5: =+Risultati!AV4 -> 1068841 | DE5: =IF($CX5>0,(DD5/$CX5),"0") -> 0.67783947 | DF5: =+Risultati!AJ4 -> 825229 | DG5: =IF($CX5>0,(DF5/$CX5),"0") -> 0.52334518 | DH5: =+DD5-DF5 -> 243612 | DI5: =IF($CX5>0,(DH5/$CX5),"0") -> 0.15449429 | DJ5: =+Risultati!AW4 -> 3702 | DK5: =IF($CX5>0,(DJ5/$CX5),"0") -> 0.0023477409 | DL5: =+CX5 -> 1576835 | DM5: =IF($CX5>0,(DL5/$CX5),"0") -> 1
B6: =+Risultati!B5 -> PAC 2000 A SOCIETA' COOPERATIVA | C6: =+Risultati!C5 -> 00163040546 | D6: =IF(YEAR(Risultati!D5)=1900,(MID(Risultati!$AP$1,29,4)),YEAR(Risultati!D5)) -> 2023 | E6: =+Risultati!E5 -> Dettagliato | F6: =(LEFT(Risultati!AN5,2)&"-")&VLOOKUP((LEFT(Risultati!AN5,2)),ateco!$B$4:$C$93,2,FALSE) -> 46-Commercio all'ingrosso (escluso quello di autoveicoli e di motocicli) | G6: =SUBSTITUTE((Risultati!AN5&"-"&Risultati!AO5),",",";") -> 463890-Commercio all'ingrosso di altri prodotti alimentari | I6: =+Risultati!G5 -> 3939071 | J6: =IF(L6<>0,(I6/L6),"0") -> 1 | L6: =+Risultati!G5+Risultati!H5 -> 3939071 | M6: =IF(L6<>0,(L6/(L6+U6)),"0") -> 0.86802644 | O6: =+Risultati!I5+Risultati!J5 -> 4026552 | P6: =IF(L6<>0,(O6/(L6+U6)),"0") -> 0.88730404 | R6: =+L6-O6 -> -87481 | S6: =IF(L6<>0,(R6/(L6+U6)),"0") -> -0.019277596 | U6: =+Risultati!F5-(Risultati!G5+Risultati!H5) -> 598891 | V6: =IF(L6<>0,(U6/(L6+U6)),"0") -> 0.13197356 | X6: =+U6+R6 -> 511410 | Y6: =IF(L6<>0,(X6/(L6+U6)),"0") -> 0.11269596 | AA6: =+Risultati!K5 -> 337244 | AB6: =IF(L6<>0,(AA6/(L6+U6)),"0") -> 0.07431618 | AD6: =+Risultati!L5 -> 40571 | AE6: =IF(L6<>0,(AD6/(L6+U6)),"0") -> 0.0089403569 | AG6: =+Risultati!M5+Risultati!P5+Risultati!Q5 -> 26759 | AH6: =IF(L6<>0,(AG6/(L6+U6)),"0") -> 0.0058966999 | AJ6: =+X6-AA6-AD6-AG6 -> 106836 | AK6: =IF(L6<>0,(AJ6/(L6+U6)),"0") -> 0.023542727 | AM6: =+Risultati!N5 -> 31947 | AN6: =IF(L6<>0,(AM6/(L6+U6)),"0") -> 0.0070399444 | AP6: =+AJ6-AM6 -> 74889 | AQ6: =IF(L6<>0,(AP6/(L6+U6)),"0") -> 0.016502783 | AS6: =+Risultati!O5 -> 35158 | AT6: =IF(L6<>0,(AS6/(L6+U6)),"0") -> 0.0077475307 | AV6: =+AP6-AS6 -> 39731 | AW6: =IF(L6<>0,(AV6/(L6+U6)),"0") -> 0.0087552518 | AY6: =+Risultati!R5+Risultati!S5 -> 10320 | AZ6: =IF(L6<>0,(AY6/(L6+U6)),"0") -> 0.0022741486 | BB6: =+Risultati!T5 -> 0 | BC6: =IF(L6<>0,(BB6/(L6+U6)),"0") -> 0 | BE6: =+Risultati!U5 -> 7868 | BF6: =IF(L6<>0,(BE6/(L6+U6)),"0") -> 0.001733818 | BH6: =+AV6+AY6+BB6-BE6 -> 42183 | BI6: =IF(L6<>0,(+BH6/(L6+U6)),"0") -> 0.0092955825 | BK6: =IF(ISNUMBER(Risultati!X5/100),(Risultati!X5/100)) -> 0.09467291 | BL6: =IF(ISNUMBER(Risultati!Y5/100),(Risultati!Y5/100)) -> 0.17621953 | BM6: =IF(ISNUMBER(Risultati!Z5/100),(Risultati!Z5/100)) -> 0.63940179 | BN6: =IF(AND(Risultati!AY5<0,calcoli!AP6<0),-IF(ISNUMBER(Risultati!AA5/100),(Risultati!AA5/100)),IF(ISNUMBER(Risultati!AA5/100),(Risultati!AA5/100))) -> 0.18448107 | BO6: =+BI6 -> 0.0092955825 | BP6: =IF(Risultati!AB5>0,(AV6/Risultati!AB5),"0") -> 0.024285081 | BQ6: =IF(Risultati!AG5<>0,(BH6/Risultati!AG5),"0") -> 0.053797779 | BR6: =+BI6 -> 0.0092955825 | BS6: =IF(Risultati!AB5>0,(Risultati!G5/Risultati!AB5),"0") -> 2.4077083 | BT6: =IF(Risultati!AG5<>0,(Risultati!AB5/Risultati!AG5),"0") -> 2.0864925 | BU6: =IF(AND(Risultati!G5>0,(Risultati!AE5-Risultati!AF5)>=0),((Risultati!AE5-Risultati!AF5)/Risultati!G5*360),"0") -> 14.626667 | BV6: =IF(OR(E6="abbreviato",Risultati!G5=0),"0",((Risultati!AC5+Risultati!AD5)/Risultati!G5*360)) -> 25.33508 | BW6: =IF(OR(E6="abbreviato",Risultati!G5=0,SUM(Risultati!I5+Risultati!K5+Risultati!M5)=0),"0",(((Risultati!AH5+Risultati!AI5)/(Risultati!I5+Risultati!K5+Risultati!N5)*360))) -> 57.586209 | BX6: =IF(Risultati!AB5>0,(+Risultati!AG5/Risultati!AB5),"0") -> 0.47927324 | BY6: =IF(OR(E6="abbreviato",Risultati!G5=0),"0",(((Risultati!AK5-(Risultati!AL5+Risultati!AM5))/Risultati!G5))) -> -0.010046024 | BZ6: =IF(Risultati!G5>0,(Risultati!AJ5/Risultati!G5),"0") -> 0.1991731 | CB6: =+Risultati!AP5 -> 3026 | CC6: =IF($CX6>0,(CB6/$CX6),"0") -> 0.0018530324 | CD6: =+Risultati!AQ5 -> 37853 | CE6: =IF($CX6>0,(CD6/$CX6),"0") -> 0.023180051 | CF6: =+Risultati!AR5 -> 365022 | CG6: =IF($CX6>0,(CF6/$CX6),"0") -> 0.22352861 | CH6: =+Risultati!AS5 -> 386597 | CI6: =IF($CX6>0,(CH6/$CX6),"0") -> 0.2367405 | CJ6: =+CH6+CF6+CD6 -> 789472 | CK6: =IF($CX6>0,(CJ6/$CX6),"0") -> 0.48344916 | CL6: =+Risultati!AE5+Risultati!AF5 -> 160043 | CM6: =IF($CX6>0,(CL6/$CX6),"0") -> 0.098005571 | CN6: =+Risultati!AT5 -> 540065 | CO6: =IF($CX6>0,(CN6/$CX6),"0") -> 0.33071974 | CP6: =+Risultati!AU5 -> 50083 | CQ6: =IF($CX6>0,(CP6/$CX6),"0") -> 0.030669339 | CR6: =+Risultati!AL5 -> 87591 | CS6: =IF($CX6>0,(CR6/$CX6),"0") -> 0.053638122 | CT6: =+CR6+CP6+CN6+CL6 -> 837782 | CU6: =IF($CX6>0,(CT6/$CX6),"0") -> 0.51303277 | CV6: =+Risultati!AX5 -> 5745 | CW6: =IF($CX6>0,(CV6/$CX6),"0") -> 0.0035180671 | CX6: =+CV6+CT6+CJ6 -> 1632999 | CY6: =IF($CX6>0,(CX6/$CX6),"0") -> 1 | CZ6: =+Risultati!AG5 -> 784103 | DA6: =IF($CX6>0,(CZ6/$CX6),"0") -> 0.48016135 | DB6: =+DL6-CZ6-DD6-DJ6 -> 28392 | DC6: =IF($CX6>0,(DB6/$CX6),"0") -> 0.017386416 | DD6: =+Risultati!AV5 -> 815565 | DE6: =IF($CX6>0,(DD6/$CX6),"0") -> 0.49942774 | DF6: =+Risultati!AJ5 -> 784557 | DG6: =IF($CX6>0,(DF6/$CX6),"0") -> 0.48043936 | DH6: =+DD6-DF6 -> 31008 | DI6: =IF($CX6>0,(DH6/$CX6),"0") -> 0.018988377 | DJ6: =+Risultati!AW5 -> 4939 | DK6: =IF($CX6>0,(DJ6/$CX6),"0") -> 0.0030244966 | DL6: =+CX6 -> 1632999 | DM6: =IF($CX6>0,(DL6/$CX6),"0") -> 1
